<mujoco model="gecko">
  <compiler angle="degree" coordinate="local" inertiafromgeom="true"/>
  <option integrator="RK4" timestep="0.01"/>

  <custom>
    <numeric data="0.0 0.0 0.55 1.0 0.0 0.0 0.0 0.0 1.0 0.0 -1.0 0.0 -1.0 0.0 1.0" name="init_qpos"/>
  </custom>

  <default>
    <joint armature="1" damping="1" limited="true"/>
    <geom conaffinity="0" condim="3" density="5.0" friction="1 0.5 0.5" margin="0.01" rgba="0.8 0.6 0.4 1"/>
  </default>

  <asset>
    <texture builtin="gradient" height="100" rgb1="1 1 1" rgb2="0 0 0" type="skybox" width="100"/>
    <texture builtin="flat" height="1278" mark="cross" markrgb="1 1 1" name="texgeom" random="0.01" rgb1="0.8 0.6 0.4" rgb2="0.8 0.6 0.4" type="cube" width="127"/>
    <texture builtin="checker" height="100" name="texplane" rgb1="0 0 0" rgb2="0.8 0.8 0.8" type="2d" width="100"/>
    <material name="MatPlane" reflectance="0.5" shininess="1" specular="1" texrepeat="60 60" texture="texplane"/>
    <material name="geom" texture="texgeom" texuniform="true"/>
  </asset>

  <worldbody>
    <light cutoff="100" diffuse="1 1 1" dir="-0 0 -1.3" directional="true" exponent="1" pos="0 0 1.3" specular=".1 .1 .1"/>
    <geom conaffinity="1" condim="3" material="MatPlane" name="floor" pos="0.0 0.0 0.0" rgba="0.8 0.9 0.8 1" size="40 40 40" type="plane"/>

    <!-- ====== Gecko ====== -->
    <body name="torso" pos="0.0 0.0 0.75">
      <geom name="head_geom" pos="0.0 0.0 0.0" size="0.25" type="sphere"/>
      <joint armature="0.0" damping="0.0" limited="false" margin="0.01" name="root" pos="0.0 0.0 0.0" type="free"/>

      <body name="front_right_leg" pos="0.0 0.0 0.0">
        <geom fromto="0.0 0.0 0.0 -0.2 0.0 0.0" name="front_right_aux_geom" size="0.08" type="capsule"/>

        <body name="front_right_aux" pos="-0.2 0.0 0.0" axisangle="0 1 0 -15">
          <joint name="hip0" pos="0.0 0.0 0.0" axis="0 0 1" range="-30 30" type="hinge"/>
          <geom fromto="0.0 0.0 0.0 -0.35 0.0 0.0" name="front_right_leg_geom" size="0.08" type="capsule"/>

          <body pos="-0.35 0.0 0.0" axisangle="0 1 0 -15">
            <joint name="ankle0" pos="0.0 0.0 0.0" axis="0 0 1" range="-30 30" type="hinge"/>
            <geom fromto="0.0 0.0 0.0 -0.35 0.0 0.0" name="front_right_ankle_geom" size="0.08" type="capsule"/>
          </body>
        </body>
      </body>

      <body name="front_left_leg" pos="0.0 0.0 0.0">
        <geom fromto="0.0 0.0 0.0 0.2 0.0 0.0" name="front_left_aux_geom" size="0.08" type="capsule"/>

        <body name="front_left_aux" pos="0.2 0.0 0.0" axisangle="0 1 0 15">
          <joint name="hip1" pos="0.0 0.0 0.0" axis="0 0 1" range="-30 30" type="hinge"/>
          <geom fromto="0.0 0.0 0.0 0.35 0.0 0.0" name="front_left_leg_geom" size="0.08" type="capsule"/>

          <body pos="0.35 0.0 0.0" axisangle="0 1 0 15">
            <joint name="ankle1" pos="0.0 0.0 0.0" axis="0 0 1" range="-30 30" type="hinge"/>
            <geom fromto="0.0 0.0 0.0 0.35 0.0 0.0" name="front_left_ankle_geom" size="0.08" type="capsule"/>
          </body>
        </body>
      </body>

      <body name="trunk" pos="0.0 0.6 0.0">
        <geom name="trunk_geom" pos="0.0 0.0 0.0" size="0.25" type="sphere"/>
        <geom name="connector0" pos="0.0 -0.3 0.0" size="0.1" type="sphere"/>
        <joint name="joint0" pos="0.0 -0.3 0.0" axis="0 0 1" range="-45 45" type="hinge"/> 

        <body name="back" pos="0.0 0.6 0.0">
          <geom name="back_geom" pos="0.0 0.0 0.0" size="0.25" type="sphere"/>
          <geom name="connector1" pos="0.0 -0.3 0.0" size="0.1" type="sphere"/>
          <joint name="joint1" pos="0.0 -0.3 0.0" axis="0 0 1" range="-45 45" type="hinge"/>

          <body name="back_right_leg" pos="0.0 0.0 0.0">
            <geom fromto="0.0 0.0 0.0 -0.2 0.0 0.0" name="back_right_aux_geom" size="0.08" type="capsule"/>

            <body name="back_right_aux" pos="-0.2 0.0 0.0" axisangle="0 1 0 -15">
              <joint name="hip2" pos="0.0 0.0 0.0" axis="0 0 1" range="-30 30" type="hinge"/>
              <geom fromto="0.0 0.0 0.0 -0.35 0.0 0.0" name="back_right_leg_geom" size="0.08" type="capsule"/>

              <body pos="-0.35 0.0 0.0" axisangle="0 1 0 -15">
                <joint name="ankle2" pos="0.0 0.0 0.0" axis="0 0 1" range="-30 30" type="hinge"/>
                <geom fromto="0.0 0.0 0.0 -0.35 0.0 0.0" name="back_right_ankle_geom" size="0.08" type="capsule"/>
              </body>
            </body>
          </body>

          <body name="back_left_leg" pos="0.0 0.0 0.0">
            <geom fromto="0.0 0.0 0.0 0.2 0.0 0.0" name="back_left_aux_geom" size="0.08" type="capsule"/>

            <body name="back_left_aux" pos="0.2 0.0 0.0" axisangle="0 1 0 15">
              <joint name="hip3" pos="0.0 0.0 0.0" axis="0 0 1" range="-30 30" type="hinge"/>
              <geom fromto="0.0 0.0 0.0 0.35 0.0 0.0" name="back_left_leg_geom" size="0.08" type="capsule"/>

              <body pos="0.35 0.0 0.0" axisangle="0 1 0 15">
                <joint name="ankle3" pos="0.0 0.0 0.0" axis="0 0 1" range="-30 30" type="hinge"/>
                <geom fromto="0.0 0.0 0.0 0.35 0.0 0.0" name="back_left_ankle_geom" size="0.08" type="capsule"/>
              </body>
            </body>
          </body>
        </body>
      </body>
    </body>
  </worldbody>

  <actuator>
    <motor ctrllimited="true" ctrlrange="-1.0 1.0" joint="hip0" gear="150"/>
    <motor ctrllimited="true" ctrlrange="-1.0 1.0" joint="ankle0" gear="150"/>
    <motor ctrllimited="true" ctrlrange="-1.0 1.0" joint="hip1" gear="150"/>
    <motor ctrllimited="true" ctrlrange="-1.0 1.0" joint="ankle1" gear="150"/>
    <motor ctrllimited="true" ctrlrange="-1.0 1.0" joint="hip2" gear="150"/>
    <motor ctrllimited="true" ctrlrange="-1.0 1.0" joint="ankle2" gear="150"/>
    <motor ctrllimited="true" ctrlrange="-1.0 1.0" joint="hip3" gear="150"/>
    <motor ctrllimited="true" ctrlrange="-1.0 1.0" joint="ankle3" gear="150"/>
  </actuator>
</mujoco>